#VRML_SIM R2025a utf8

EXTERNPROTO "https://raw.githubusercontent.com/cyberbotics/webots/R2025a/projects/objects/backgrounds/protos/TexturedBackground.proto"
EXTERNPROTO "https://raw.githubusercontent.com/cyberbotics/webots/R2025a/projects/objects/backgrounds/protos/TexturedBackgroundLight.proto"
EXTERNPROTO "https://raw.githubusercontent.com/cyberbotics/webots/R2025a/projects/objects/floors/protos/Floor.proto"
EXTERNPROTO "https://raw.githubusercontent.com/cyberbotics/webots/R2025a/projects/objects/factory/containers/protos/WoodenBox.proto"
EXTERNPROTO "https://raw.githubusercontent.com/cyberbotics/webots/R2025a/projects/robots/kuka/youbot/protos/KukaBox.proto"
EXTERNPROTO "https://raw.githubusercontent.com/cyberbotics/webots/R2025a/projects/objects/apartment_structure/protos/Wall.proto"
EXTERNPROTO "https://raw.githubusercontent.com/cyberbotics/webots/R2025a/projects/objects/toys/protos/RubberDuck.proto"
EXTERNPROTO "https://raw.githubusercontent.com/cyberbotics/webots/R2025a/projects/objects/kitchen/utensils/protos/Wineglass.proto"
EXTERNPROTO "https://raw.githubusercontent.com/cyberbotics/webots/R2025a/projects/objects/balls/protos/PingPongBall.proto"
EXTERNPROTO "https://raw.githubusercontent.com/cyberbotics/webots/R2025a/projects/robots/kuka/youbot/protos/BodyMesh.proto"
EXTERNPROTO "https://raw.githubusercontent.com/cyberbotics/webots/R2025a/projects/robots/kuka/youbot/protos/Arm0Mesh.proto"
EXTERNPROTO "https://raw.githubusercontent.com/cyberbotics/webots/R2025a/projects/robots/kuka/youbot/protos/Arm1Mesh.proto"
EXTERNPROTO "https://raw.githubusercontent.com/cyberbotics/webots/R2025a/projects/robots/kuka/youbot/protos/Arm2Mesh.proto"
EXTERNPROTO "https://raw.githubusercontent.com/cyberbotics/webots/R2025a/projects/robots/kuka/youbot/protos/Arm3Mesh.proto"
EXTERNPROTO "https://raw.githubusercontent.com/cyberbotics/webots/R2025a/projects/robots/kuka/youbot/protos/Arm4Mesh.proto"
EXTERNPROTO "https://raw.githubusercontent.com/cyberbotics/webots/R2025a/projects/robots/kuka/youbot/protos/Arm5Mesh.proto"
EXTERNPROTO "https://raw.githubusercontent.com/cyberbotics/webots/R2025a/projects/robots/kuka/youbot/protos/FingerMesh.proto"
EXTERNPROTO "https://raw.githubusercontent.com/cyberbotics/webots/R2025a/projects/robots/kuka/youbot/protos/InteriorWheel.proto"
EXTERNPROTO "https://raw.githubusercontent.com/cyberbotics/webots/R2025a/projects/robots/kuka/youbot/protos/ExteriorWheel.proto"
EXTERNPROTO "https://raw.githubusercontent.com/cyberbotics/webots/R2025a/projects/robots/kuka/youbot/protos/PlateMesh.proto"

WorldInfo {
  info [
    "Simulation of the KUKA youBot robot."
    "This model includes an accurate and fast simulation of the Meccanum wheels."
    "The robot can be equiped with various sensors (including the Microsoft Kinect) and configured with zero, one or two arms."
  ]
  title "KUKA youBot"
  basicTimeStep 16
  contactProperties [
    ContactProperties {
      material1 "InteriorWheelMat"
      coulombFriction [
        0, 2, 0
      ]
      frictionRotation -0.785398 0
      bounce 0
      forceDependentSlip [
        10, 0
      ]
    }
    ContactProperties {
      material1 "ExteriorWheelMat"
      coulombFriction [
        0, 2, 0
      ]
      frictionRotation 0.785398 0
      bounce 0
      forceDependentSlip [
        10, 0
      ]
    }
  ]
}
Viewpoint {
  orientation 0.16893023285231248 0.2879647585106567 -0.94262340003013 2.0212248579164966
  position 1.245317355309921 1.9056940128545534 1.6608354691540668
  follow "youBot"
}
TexturedBackground {
}
TexturedBackgroundLight {
}
Floor {
  size 100 100
}
PingPongBall {
  translation -4.81 -7.09 0.42
}
Wineglass {
  translation 0.36 -5.49 0.41
}
RubberDuck {
  translation -5.68 -1.29 0.43
  rotation 0 0 -1 3.14159
}
Wall {
  translation -5.04 -2.43 0.499993
  rotation 0.9999999999875162 -4.263819999946772e-06 -2.6052699999674764e-06 -1.5707953071795862
  name "wall(26)"
}
Wall {
  translation -2.8 -5.49 0.499993
  rotation -1.83880943097924e-06 0.7071067811853522 -0.7071067811853522 -3.1415853071795863
  name "wall(23)"
}
Wall {
  translation -5.41 -5.49 0.499998
  rotation -1.83880943097924e-06 0.7071067811853522 -0.7071067811853522 -3.1415853071795863
  name "wall(25)"
}
Wall {
  translation -2.53 1.7 0.500001
  rotation -0.5773509358537164 0.5773519358536053 -0.5773479358540498 2.0944
  name "wall(1)"
}
Wall {
  translation -4.91 1.7 0.500035
  rotation -0.5773509358537164 0.5773519358536053 -0.5773479358540498 2.0944
  name "wall(2)"
}
Wall {
  translation -7.25 1.7 0.500046
  rotation -0.5773509358537164 0.5773519358536053 -0.5773479358540498 2.0944
  name "wall(3)"
}
Wall {
  translation -0.18 1.7 0.500001
  rotation -0.5773509358537164 0.5773519358536053 -0.5773479358540498 2.0944
}
Wall {
  translation 2.12 1.6 0.499992
  rotation -1.83880943097924e-06 0.7071067811853522 -0.7071067811853522 -3.1415853071795863
  name "wall(4)"
}
Wall {
  translation 2.12 -0.78 0.499992
  rotation -1.83880943097924e-06 0.7071067811853522 -0.7071067811853522 -3.1415853071795863
  name "wall(5)"
}
Wall {
  translation -0.8 1.59 0.499991
  rotation -1.83880943097924e-06 0.7071067811853522 -0.7071067811853522 -3.1415853071795863
  name "wall(16)"
}
Wall {
  translation -1.47 -0.8 0.499991
  rotation -0.5773509358537164 0.5773519358536053 -0.5773479358540498 2.0944
  name "wall(17)"
}
Wall {
  translation -1.47 -2.43 0.499991
  rotation -0.5773509358537164 0.5773519358536053 -0.5773479358540498 2.0944
  name "wall(18)"
}
Wall {
  translation -5.04 -2.43 0.499993
  rotation -0.5773509358537164 0.5773519358536053 -0.5773479358540498 2.0944
  name "wall(24)"
}
Wall {
  translation -1.47 -4.83 0.499991
  rotation -0.5773509358537164 0.5773519358536053 -0.5773479358540498 2.0944
  name "wall(20)"
}
Wall {
  translation 0.79 -2.43 0.499991
  rotation -1.83880943097924e-06 0.7071067811853522 -0.7071067811853522 -3.1415853071795863
  name "wall(19)"
}
Wall {
  translation -0.26 -4.78 0.499991
  rotation -1.83880943097924e-06 0.7071067811853522 -0.7071067811853522 -3.1415853071795863
  name "wall(21)"
}
Wall {
  translation -0.26 -5.53 0.499991
  rotation -1.83880943097924e-06 0.7071067811853522 -0.7071067811853522 -3.1415853071795863
  name "wall(22)"
}
Wall {
  translation 2.12 -3.16 0.499992
  rotation -1.83880943097924e-06 0.7071067811853522 -0.7071067811853522 -3.1415853071795863
  name "wall(6)"
}
Wall {
  translation 2.12 -5.55 0.499992
  rotation -1.83880943097924e-06 0.7071067811853522 -0.7071067811853522 -3.1415853071795863
  name "wall(7)"
}
Wall {
  translation 2.05 -7.85 0.499992
  rotation -0.5773499358526729 -0.5773479358528951 0.5773529358523396 2.09439
  name "wall(8)"
}
Wall {
  translation -0.31 -7.85 0.500007
  rotation -0.5773499358526729 -0.5773479358528951 0.5773529358523396 2.09439
  name "wall(9)"
}
Wall {
  translation -2.7 -7.85 0.500032
  rotation -0.5773499358526729 -0.5773479358528951 0.5773529358523396 2.09439
  name "wall(10)"
}
Wall {
  translation -5.1 -7.85 0.500048
  rotation -0.5773499358526729 -0.5773479358528951 0.5773529358523396 2.09439
  name "wall(11)"
}
Wall {
  translation -7.36 -7.76 0.500048
  rotation -0.9999999999842972 4.964189999922048e-06 2.6004699999591653e-06 1.5708
  name "wall(12)"
}
Wall {
  translation -7.36 -5.37 0.500048
  rotation -0.9999999999842972 4.964189999922048e-06 2.6004699999591653e-06 1.5708
  name "wall(13)"
}
Wall {
  translation -7.36 -2.97 0.500048
  rotation -0.9999999999842972 4.964189999922048e-06 2.6004699999591653e-06 1.5708
  name "wall(14)"
}
Wall {
  translation -7.36 -0.58 0.500034
  rotation -0.9999999999842972 4.964189999922048e-06 2.6004699999591653e-06 1.5708
  name "wall(15)"
}
WoodenBox {
  translation -1.20455 -0.35878 0.2
  rotation 0 0 1 -1.5707963267948966
  name "wooden box(1)"
  size 0.6 0.6 0.4
}
WoodenBox {
  translation 0.15545 -5.26878 0.2
  rotation 0 0 1 -1.5707963267948966
  name "wooden box(2)"
  size 0.6 0.6 0.4
}
WoodenBox {
  translation -4.99455 -7.28878 0.2
  rotation 0 0 1 -1.5707963267948966
  name "wooden box(3)"
  size 0.6 0.6 0.4
}
WoodenBox {
  translation -5.49455 -1.37878 0.2
  rotation 0 0 1 -1.5707963267948966
  name "wooden box(4)"
  size 0.6 0.6 0.4
}
KukaBox {
  translation -1.39737 -0.322899 0.41876
  rotation 0 0 1 -1.5707963267948966
}
Robot {
  translation 0 0 0.102838
  children [
    Camera {
      translation 0.3 0 0.2
      width 640
      height 480
    }
    InertialUnit {
    }
    GPS {
    }
    Lidar {
      translation 0.3 0 0
      name "lidar_sensor"
      horizontalResolution 128
      numberOfLayers 1
      maxRange 2
    }
    BodyMesh {
    }
    Group {
    }
    DEF ARM Solid {
      translation 0.156 0 0
      children [
        Arm0Mesh {
        }
        HingeJoint {
          jointParameters HingeJointParameters {
            axis 0 0 1
            anchor 0 0 0.077
          }
          device [
            RotationalMotor {
              name "arm1"
              maxVelocity 1.5708
              minPosition -2.9496
              maxPosition 2.9496
              maxTorque 9.5
            }
            PositionSensor {
              name "arm1sensor"
            }
          ]
          endPoint Solid {
            translation 0 0 0.077
            children [
              Arm1Mesh {
              }
              HingeJoint {
                jointParameters HingeJointParameters {
                  axis 0 -1 0
                  anchor 0.033 0 0.07
                }
                device [
                  RotationalMotor {
                    name "arm2"
                    maxVelocity 1.5708
                    minPosition -1.13446
                    maxPosition 1.5708
                    maxTorque 9.5
                  }
                  PositionSensor {
                    name "arm2sensor"
                  }
                ]
                endPoint Solid {
                  translation 0.033 0 0.07
                  rotation 0 -1 0 0
                  children [
                    Arm2Mesh {
                    }
                    HingeJoint {
                      jointParameters HingeJointParameters {
                        axis 0 -1 0
                        anchor 0 0 0.155
                      }
                      device [
                        RotationalMotor {
                          name "arm3"
                          maxVelocity 1.5708
                          minPosition -2.63545
                          maxPosition 2.54818
                          maxTorque 6
                        }
                        PositionSensor {
                          name "arm3sensor"
                        }
                      ]
                      endPoint Solid {
                        translation 0 0 0.155
                        rotation 0 -1 0 0
                        children [
                          Arm3Mesh {
                          }
                          HingeJoint {
                            jointParameters HingeJointParameters {
                              axis 0 -1 0
                              anchor 0 0 0.135
                            }
                            device [
                              RotationalMotor {
                                name "arm4"
                                maxVelocity 1.5708
                                minPosition -1.78024
                                maxPosition 1.78024
                                maxTorque 2
                              }
                              PositionSensor {
                                name "arm4sensor"
                              }
                            ]
                            endPoint Solid {
                              translation 0 0 0.135
                              rotation 0 -1 0 0
                              children [
                                Arm4Mesh {
                                }
                                HingeJoint {
                                  jointParameters HingeJointParameters {
                                    axis 0 0 1
                                    anchor 0 0 0.081
                                  }
                                  device [
                                    RotationalMotor {
                                      name "arm5"
                                      maxVelocity 1.5708
                                      minPosition -2.92343
                                      maxPosition 2.92343
                                      maxTorque 1
                                    }
                                    PositionSensor {
                                      name "arm5sensor"
                                    }
                                  ]
                                  endPoint Solid {
                                    translation 0 0 0.081
                                    children [
                                      Arm5Mesh {
                                      }
                                      SliderJoint {
                                        jointParameters JointParameters {
                                          axis 0 1 0
                                        }
                                        device [
                                          LinearMotor {
                                            name "finger::left"
                                            maxPosition 0.025
                                            maxForce 100
                                          }
                                          PositionSensor {
                                            name "finger::leftsensor"
                                          }
                                        ]
                                        endPoint Solid {
                                          translation 0 0 0.09
                                          rotation 1 0 0 4.71239
                                          children [
                                            FingerMesh {
                                            }
                                          ]
                                          name "finger::left"
                                          boundingObject DEF FINGER_BO Group {
                                            children [
                                              Pose {
                                                translation 0 -0.031 0.015
                                                children [
                                                  Box {
                                                    size 0.014 0.032 0.009
                                                  }
                                                ]
                                              }
                                              Pose {
                                                translation 0 -0.007 0.01
                                                children [
                                                  Box {
                                                    size 0.014 0.015 0.019
                                                  }
                                                ]
                                              }
                                            ]
                                          }
                                          physics DEF FINGER_PH Physics {
                                            density -1
                                            mass 0.03
                                            centerOfMass [
                                              0 -0.02 0.01
                                            ]
                                            inertiaMatrix [
                                              6.84034e-06 1.41763e-06 6.40271e-06
                                              0 0 8.29319e-07
                                            ]
                                          }
                                        }
                                      }
                                      SliderJoint {
                                        jointParameters JointParameters {
                                          axis 0 -1 0
                                        }
                                        device [
                                          LinearMotor {
                                            name "finger::right"
                                            maxPosition 0.025
                                            maxForce 100
                                          }
                                          PositionSensor {
                                            name "finger::rightsensor"
                                          }
                                        ]
                                        endPoint Solid {
                                          translation 0 0 0.09
                                          rotation 0 -0.7071067811865476 0.7071067811865476 3.14159
                                          children [
                                            FingerMesh {
                                            }
                                          ]
                                          name "finger::right"
                                          boundingObject USE FINGER_BO
                                          physics USE FINGER_PH
                                        }
                                      }
                                    ]
                                    boundingObject Pose {
                                      translation 0 0 0.045
                                      children [
                                        Box {
                                          size 0.025 0.07 0.09
                                        }
                                      ]
                                    }
                                    physics Physics {
                                      density -1
                                      mass 0.251
                                      centerOfMass [
                                        0 0 0.045
                                      ]
                                      inertiaMatrix [
                                        0.000271917 0.000182498 0.000115565
                                        0 0 0
                                      ]
                                    }
                                  }
                                }
                              ]
                              boundingObject Group {
                                children [
                                  Pose {
                                    translation 0 0 0.056
                                    children [
                                      Box {
                                        size 0.05 0.095 0.05
                                      }
                                    ]
                                  }
                                  Pose {
                                    translation 0 -0.024 0.003
                                    rotation 1 0 0 -1.5708
                                    children [
                                      Cylinder {
                                        height 0.047
                                        radius 0.027
                                      }
                                    ]
                                  }
                                ]
                              }
                              physics Physics {
                                density -1
                                mass 0.877
                                centerOfMass [
                                  0 0 0.026
                                ]
                                inertiaMatrix [
                                  0.00152517 0.00103897 0.000837339
                                  0 0 -0.00015098
                                ]
                              }
                            }
                          }
                        ]
                        boundingObject Pose {
                          translation 0 0.0225 0.065
                          children [
                            Box {
                              size 0.06 0.045 0.19
                            }
                          ]
                        }
                        physics Physics {
                          density -1
                          mass 0.934
                          centerOfMass [
                            0 0.0225 0.065
                          ]
                          inertiaMatrix [
                            0.0029674 0.00308998 0.000437812
                            0 0 -5.99276e-20
                          ]
                        }
                      }
                    }
                  ]
                  boundingObject Pose {
                    translation 0 -0.03 0.078
                    children [
                      Box {
                        size 0.07 0.06 0.21
                      }
                    ]
                  }
                  physics Physics {
                    density -1
                    mass 1.155
                    centerOfMass [
                      0 -0.03 0.078
                    ]
                    inertiaMatrix [
                      0.00459113 0.00471625 0.000818125
                      0 0 1.56701e-20
                    ]
                  }
                }
              }
            ]
            boundingObject Pose {
              translation 0.032 0.023 0.07
              rotation 1 0 0 -1.5708
              children [
                Cylinder {
                  height 0.046
                  radius 0.036
                }
              ]
            }
            physics Physics {
              density -1
              mass 2.412
              centerOfMass [
                0.015 0.01 0.05
              ]
              inertiaMatrix [
                0.00257923 0.00322484 0.0023115
                -0.000533052 -0.00082008 -0.00062712
              ]
            }
          }
        }
      ]
      name "arm"
      boundingObject Pose {
        translation 0 0 0.04
        children [
          Cylinder {
            height 0.08
            radius 0.078
          }
        ]
      }
      physics Physics {
        density -1
        mass 0.845
        centerOfMass [
          0 0 0.04
        ]
        inertiaMatrix [
          0.00173591 0.00173591 0.00257049
          0 0 -3.06558e-09
        ]
      }
    }
    DEF WHEEL1 InteriorWheel {
      translation 0.228 -0.158 -0.055
      anchor 0.228 -0.158 -0.055
      name "wheel1"
      sensorName "wheel1sensor"
    }
    DEF WHEEL2 ExteriorWheel {
      translation 0.228 0.158 -0.055
      anchor 0.228 0.158 -0.055
      name "wheel2"
      sensorName "wheel2sensor"
    }
    DEF WHEEL3 ExteriorWheel {
      translation -0.228 -0.158 -0.055
      anchor -0.228 -0.158 -0.055
      name "wheel3"
      sensorName "wheel3sensor"
    }
    DEF WHEEL4 InteriorWheel {
      translation -0.228 0.158 -0.055
      anchor -0.228 0.158 -0.055
      name "wheel4"
      sensorName "wheel4sensor"
    }
    DEF PLATE Solid {
      translation -0.155 0 0
      children [
        PlateMesh {
        }
      ]
      name "plate"
      boundingObject Group {
        children [
          Pose {
            translation 0.008 0 0.045
            children [
              Box {
                size 0.25 0.17 0.007
              }
            ]
          }
          Pose {
            translation -0.015 0.112 0.045
            rotation 0 0 1 -0.13
            children [
              Box {
                size 0.17 0.08 0.007
              }
            ]
          }
          Pose {
            translation -0.015 -0.112 0.045
            rotation 0 0 1 0.13
            children [
              Box {
                size 0.17 0.08 0.007
              }
            ]
          }
          Pose {
            translation 0.076 0.084 0.045
            rotation 0 0 1 0.81
            children [
              Box {
                size 0.08 0.08 0.007
              }
            ]
          }
          Pose {
            translation 0.076 -0.084 0.045
            rotation 0 0 1 -0.81
            children [
              Box {
                size 0.08 0.08 0.007
              }
            ]
          }
        ]
      }
      physics Physics {
        density -1
        mass 0.5
      }
    }
  ]
  name "youBot"
  model "KUKA youBot"
  description "KUKA youBot"
  boundingObject Group {
    children [
      Pose {
        translation 0 0 -0.045
        children [
          Box {
            size 0.34 0.34 0.09
          }
        ]
      }
      Pose {
        translation 0 0 -0.045
        children [
          Box {
            size 0.56 0.23 0.09
          }
        ]
      }
    ]
  }
  physics Physics {
    density -1
    mass 22
    centerOfMass [
      0 0 -0.045
    ]
    inertiaMatrix [
      0.166204 0.418086 0.55459
      0 0 0
    ]
  }
  controller "<extern>"
  controllerArgs [
    "demo"
  ]
}
